[2023-11-12T16:02:35.581+0000] {taskinstance.py:1159} INFO - Dependencies all met for dep_context=non-requeueable deps ti=<TaskInstance: first_dag.firs_task scheduled__2023-11-10T19:00:00+00:00 [queued]>
[2023-11-12T16:02:35.631+0000] {taskinstance.py:1159} INFO - Dependencies all met for dep_context=requeueable deps ti=<TaskInstance: first_dag.firs_task scheduled__2023-11-10T19:00:00+00:00 [queued]>
[2023-11-12T16:02:35.644+0000] {taskinstance.py:1361} INFO - Starting attempt 3 of 4
[2023-11-12T16:02:35.744+0000] {taskinstance.py:1382} INFO - Executing <Task(BashOperator): firs_task> on 2023-11-10 19:00:00+00:00
[2023-11-12T16:02:35.768+0000] {standard_task_runner.py:57} INFO - Started process 4665 to run task
[2023-11-12T16:02:35.780+0000] {standard_task_runner.py:84} INFO - Running: ['***', 'tasks', 'run', 'first_dag', 'firs_task', 'scheduled__2023-11-10T19:00:00+00:00', '--job-id', '1020', '--raw', '--subdir', 'DAGS_FOLDER/my_first_dag.py', '--cfg-path', '/tmp/tmp87l4fm74']
[2023-11-12T16:02:35.801+0000] {standard_task_runner.py:85} INFO - Job 1020: Subtask firs_task
[2023-11-12T16:02:36.007+0000] {task_command.py:416} INFO - Running <TaskInstance: first_dag.firs_task scheduled__2023-11-10T19:00:00+00:00 [running]> on host 24f204fafe4d
[2023-11-12T16:02:36.328+0000] {taskinstance.py:1662} INFO - Exporting env vars: AIRFLOW_CTX_DAG_EMAIL='yuriy.peretolchin@mail.com' AIRFLOW_CTX_DAG_OWNER='Peretolchin.YuS' AIRFLOW_CTX_DAG_ID='first_dag' AIRFLOW_CTX_TASK_ID='firs_task' AIRFLOW_CTX_EXECUTION_DATE='2023-11-10T19:00:00+00:00' AIRFLOW_CTX_TRY_NUMBER='3' AIRFLOW_CTX_DAG_RUN_ID='scheduled__2023-11-10T19:00:00+00:00'
[2023-11-12T16:02:36.344+0000] {subprocess.py:63} INFO - Tmp dir root location: /tmp
[2023-11-12T16:02:36.349+0000] {subprocess.py:75} INFO - Running command: ['/bin/bash', '-c', 'python3 /opt/***/dags/test.py']
[2023-11-12T16:02:36.383+0000] {subprocess.py:86} INFO - Output:
[2023-11-12T16:02:37.424+0000] {subprocess.py:93} INFO - python3: can't open file '/opt/***/dags/test.py': [Errno 2] No such file or directory
[2023-11-12T16:02:37.447+0000] {subprocess.py:97} INFO - Command exited with return code 2
[2023-11-12T16:02:37.510+0000] {taskinstance.py:1937} ERROR - Task failed with exception
Traceback (most recent call last):
  File "/home/airflow/.local/lib/python3.8/site-packages/airflow/operators/bash.py", line 210, in execute
    raise AirflowException(
airflow.exceptions.AirflowException: Bash command failed. The command returned a non-zero exit code 2.
[2023-11-12T16:02:37.564+0000] {taskinstance.py:1400} INFO - Marking task as UP_FOR_RETRY. dag_id=first_dag, task_id=firs_task, execution_date=20231110T190000, start_date=20231112T160235, end_date=20231112T160237
[2023-11-12T16:02:37.660+0000] {standard_task_runner.py:104} ERROR - Failed to execute job 1020 for task firs_task (Bash command failed. The command returned a non-zero exit code 2.; 4665)
[2023-11-12T16:02:37.735+0000] {local_task_job_runner.py:228} INFO - Task exited with return code 1
[2023-11-12T16:02:37.814+0000] {taskinstance.py:2778} INFO - 0 downstream tasks scheduled from follow-on schedule check
