[2023-11-12T15:57:30.146+0000] {taskinstance.py:1159} INFO - Dependencies all met for dep_context=non-requeueable deps ti=<TaskInstance: first_dag.firs_task scheduled__2023-11-10T19:00:00+00:00 [queued]>
[2023-11-12T15:57:30.234+0000] {taskinstance.py:1159} INFO - Dependencies all met for dep_context=requeueable deps ti=<TaskInstance: first_dag.firs_task scheduled__2023-11-10T19:00:00+00:00 [queued]>
[2023-11-12T15:57:30.247+0000] {taskinstance.py:1361} INFO - Starting attempt 2 of 4
[2023-11-12T15:57:30.460+0000] {taskinstance.py:1382} INFO - Executing <Task(BashOperator): firs_task> on 2023-11-10 19:00:00+00:00
[2023-11-12T15:57:30.497+0000] {standard_task_runner.py:84} INFO - Running: ['***', 'tasks', 'run', 'first_dag', 'firs_task', 'scheduled__2023-11-10T19:00:00+00:00', '--job-id', '518', '--raw', '--subdir', 'DAGS_FOLDER/my_first_dag.py', '--cfg-path', '/tmp/tmpy3hz1vkk']
[2023-11-12T15:57:30.507+0000] {standard_task_runner.py:85} INFO - Job 518: Subtask firs_task
[2023-11-12T15:57:30.512+0000] {standard_task_runner.py:57} INFO - Started process 3193 to run task
[2023-11-12T15:57:31.013+0000] {task_command.py:416} INFO - Running <TaskInstance: first_dag.firs_task scheduled__2023-11-10T19:00:00+00:00 [running]> on host 24f204fafe4d
[2023-11-12T15:57:32.030+0000] {taskinstance.py:1662} INFO - Exporting env vars: AIRFLOW_CTX_DAG_EMAIL='yuriy.peretolchin@mail.com' AIRFLOW_CTX_DAG_OWNER='Peretolchin.YuS' AIRFLOW_CTX_DAG_ID='first_dag' AIRFLOW_CTX_TASK_ID='firs_task' AIRFLOW_CTX_EXECUTION_DATE='2023-11-10T19:00:00+00:00' AIRFLOW_CTX_TRY_NUMBER='2' AIRFLOW_CTX_DAG_RUN_ID='scheduled__2023-11-10T19:00:00+00:00'
[2023-11-12T15:57:32.041+0000] {subprocess.py:63} INFO - Tmp dir root location: /tmp
[2023-11-12T15:57:32.054+0000] {subprocess.py:75} INFO - Running command: ['/bin/bash', '-c', 'python3 /opt/***/dags/test.py']
[2023-11-12T15:57:32.152+0000] {subprocess.py:86} INFO - Output:
[2023-11-12T15:57:33.361+0000] {subprocess.py:93} INFO - python3: can't open file '/opt/***/dags/test.py': [Errno 2] No such file or directory
[2023-11-12T15:57:33.386+0000] {subprocess.py:97} INFO - Command exited with return code 2
[2023-11-12T15:57:33.421+0000] {taskinstance.py:1937} ERROR - Task failed with exception
Traceback (most recent call last):
  File "/home/airflow/.local/lib/python3.8/site-packages/airflow/operators/bash.py", line 210, in execute
    raise AirflowException(
airflow.exceptions.AirflowException: Bash command failed. The command returned a non-zero exit code 2.
[2023-11-12T15:57:33.443+0000] {taskinstance.py:1400} INFO - Marking task as UP_FOR_RETRY. dag_id=first_dag, task_id=firs_task, execution_date=20231110T190000, start_date=20231112T155730, end_date=20231112T155733
[2023-11-12T15:57:33.575+0000] {standard_task_runner.py:104} ERROR - Failed to execute job 518 for task firs_task (Bash command failed. The command returned a non-zero exit code 2.; 3193)
[2023-11-12T15:57:33.632+0000] {local_task_job_runner.py:228} INFO - Task exited with return code 1
[2023-11-12T15:57:33.874+0000] {taskinstance.py:2778} INFO - 0 downstream tasks scheduled from follow-on schedule check
