[2023-11-12T15:57:30.782+0000] {taskinstance.py:1159} INFO - Dependencies all met for dep_context=non-requeueable deps ti=<TaskInstance: first_dag.firs_task manual__2023-11-12T15:51:47.357322+00:00 [queued]>
[2023-11-12T15:57:30.901+0000] {taskinstance.py:1159} INFO - Dependencies all met for dep_context=requeueable deps ti=<TaskInstance: first_dag.firs_task manual__2023-11-12T15:51:47.357322+00:00 [queued]>
[2023-11-12T15:57:30.933+0000] {taskinstance.py:1361} INFO - Starting attempt 2 of 4
[2023-11-12T15:57:31.343+0000] {taskinstance.py:1382} INFO - Executing <Task(BashOperator): firs_task> on 2023-11-12 15:51:47.357322+00:00
[2023-11-12T15:57:31.484+0000] {standard_task_runner.py:57} INFO - Started process 3195 to run task
[2023-11-12T15:57:31.525+0000] {standard_task_runner.py:84} INFO - Running: ['***', 'tasks', 'run', 'first_dag', 'firs_task', 'manual__2023-11-12T15:51:47.357322+00:00', '--job-id', '521', '--raw', '--subdir', 'DAGS_FOLDER/my_first_dag.py', '--cfg-path', '/tmp/tmpurfu88de']
[2023-11-12T15:57:31.563+0000] {standard_task_runner.py:85} INFO - Job 521: Subtask firs_task
[2023-11-12T15:57:32.184+0000] {task_command.py:416} INFO - Running <TaskInstance: first_dag.firs_task manual__2023-11-12T15:51:47.357322+00:00 [running]> on host 24f204fafe4d
[2023-11-12T15:57:32.541+0000] {taskinstance.py:1662} INFO - Exporting env vars: AIRFLOW_CTX_DAG_EMAIL='yuriy.peretolchin@mail.com' AIRFLOW_CTX_DAG_OWNER='Peretolchin.YuS' AIRFLOW_CTX_DAG_ID='first_dag' AIRFLOW_CTX_TASK_ID='firs_task' AIRFLOW_CTX_EXECUTION_DATE='2023-11-12T15:51:47.357322+00:00' AIRFLOW_CTX_TRY_NUMBER='2' AIRFLOW_CTX_DAG_RUN_ID='manual__2023-11-12T15:51:47.357322+00:00'
[2023-11-12T15:57:32.552+0000] {subprocess.py:63} INFO - Tmp dir root location: /tmp
[2023-11-12T15:57:32.562+0000] {subprocess.py:75} INFO - Running command: ['/bin/bash', '-c', 'python3 /opt/***/dags/test.py']
[2023-11-12T15:57:32.598+0000] {subprocess.py:86} INFO - Output:
[2023-11-12T15:57:33.334+0000] {subprocess.py:93} INFO - python3: can't open file '/opt/***/dags/test.py': [Errno 2] No such file or directory
[2023-11-12T15:57:33.356+0000] {subprocess.py:97} INFO - Command exited with return code 2
[2023-11-12T15:57:33.402+0000] {taskinstance.py:1937} ERROR - Task failed with exception
Traceback (most recent call last):
  File "/home/airflow/.local/lib/python3.8/site-packages/airflow/operators/bash.py", line 210, in execute
    raise AirflowException(
airflow.exceptions.AirflowException: Bash command failed. The command returned a non-zero exit code 2.
[2023-11-12T15:57:33.423+0000] {taskinstance.py:1400} INFO - Marking task as UP_FOR_RETRY. dag_id=first_dag, task_id=firs_task, execution_date=20231112T155147, start_date=20231112T155730, end_date=20231112T155733
[2023-11-12T15:57:33.608+0000] {standard_task_runner.py:104} ERROR - Failed to execute job 521 for task firs_task (Bash command failed. The command returned a non-zero exit code 2.; 3195)
[2023-11-12T15:57:33.650+0000] {local_task_job_runner.py:228} INFO - Task exited with return code 1
[2023-11-12T15:57:33.800+0000] {taskinstance.py:2778} INFO - 0 downstream tasks scheduled from follow-on schedule check
